
<?xml version="1.0"?>
<robot name="simple_car" xmlns:xacro="http://ros.org/wiki/xacro">

  <!-- Base/kroppen til bilen -->
  <link name="base_link">
    <visual>
      <geometry>
        <box size="0.5 0.3 0.1"/> <!-- Lengde x Bredde x Høyde -->
      </geometry>
      <material name="blue">
        <color rgba="0 0 1 1"/>
      </material>
    </visual>
    <collision>
      <geometry>
        <box size="0.5 0.3 0.1"/>
      </geometry>
    </collision>
    <inertial>
      <mass value="2.0"/> <!-- Set a reasonable mass for the base -->
      <origin xyz="0 0 0" rpy="0 0 0"/>
      <inertia ixx="0.1" ixy="0.0" ixz="0.0" iyy="0.1" iyz="0.0" izz="0.1"/>
    </inertial>
  </link>

  <!-- Høyre hjul -->
  <link name="right_wheel">
    <visual>
      <geometry>
        <cylinder radius="0.1" length="0.05"/> <!-- Hjul: Radius = 0.1, bredde = 0.05 -->
      </geometry>
      <material name="black">
        <color rgba="0 0 0 1"/>
      </material>
      <origin xyz="0 0 0" rpy="0 1.5708 0"/> <!-- Rotasjon rundt Y-aksen for korrekt orientering -->
    </visual>
    <collision>
      <geometry>
        <cylinder radius="0.1" length="0.05"/>
      </geometry>
      <origin xyz="0 0 0" rpy="0 1.5708 0"/>
    </collision>
    <inertial>
      <mass value="0.5"/> <!-- Set a reasonable mass for the wheel -->
      <origin xyz="0 0 0" rpy="0 1.5708 0"/>
      <inertia ixx="0.01" ixy="0.0" ixz="0.0" iyy="0.01" iyz="0.0" izz="0.01"/>
    </inertial>
  </link>

  <!-- Venstre hjul -->
  <link name="left_wheel">
    <visual>
      <geometry>
        <cylinder radius="0.1" length="0.05"/> <!-- Hjul: Radius = 0.1, bredde = 0.05 -->
      </geometry>
      <material name="black">
        <color rgba="0 0 0 1"/>
      </material>
      <origin xyz="0 0 0" rpy="0 1.5708 0"/> <!-- Roter hjulet likt som høyre hjul -->
    </visual>
    <collision>
      <geometry>
        <cylinder radius="0.1" length="0.05"/>
      </geometry>
      <origin xyz="0 0 0" rpy="0 1.5708 0"/>
    </collision>
    <inertial>
      <mass value="0.5"/> <!-- Set a reasonable mass for the wheel -->
      <origin xyz="0 0 0" rpy="0 1.5708 0"/>
      <inertia ixx="0.01" ixy="0.0" ixz="0.0" iyy="0.01" iyz="0.0" izz="0.01"/>
    </inertial>
  </link>

  <!-- Joint for høyre hjul (rotasjon rundt X-aksen) -->
  <joint name="right_wheel_joint" type="continuous">
    <parent link="base_link"/>
    <child link="right_wheel"/>
    <origin xyz="0.2 -0.15 -0.05" rpy="0 0 -1.57"/>
    <axis xyz="1 0 0"/> <!-- Rotasjon rundt X-aksen (blå akse) -->
  </joint>

  <!-- Joint for venstre hjul (rotasjon rundt X-aksen) -->
  <joint name="left_wheel_joint" type="continuous">
    <parent link="base_link"/>
    <child link="left_wheel"/>
    <origin xyz="0.2 0.15 -0.05" rpy="0 0 1.57"/>
    <axis xyz="1 0 0"/> <!-- Samme rotasjon som høyre hjul -->
  </joint>

</robot>



